Workbook

Sheet Cadastro
A1: servidor | B1: cidade | C1: ip | D1: porta | E1: camera | F1: local_nome | G1: lat | H1: lng | I1: siscop | J1: senha | K1: protocolo | L1: vms | M1: formato | N1: hostname | O1: link | P1: ativo
A2: URBS 1 | B2: CURITIBA | C2: https://monitoramento.pm.pr.gov.br/proxy_image_1/ | D2: 18601 | E2: Camera01 | F2: Brasilio Itibere x Com. Franco | G2: -25.440635 | H2: -49.25217 | I2: copom_DDTQ | J2: DDTQcopom | K2: https | L2: Digifort | M2: mjpg | N2: =$A2 -> URBS 1 | O2: =IF($P2=1,IF($L2 = "Digifort",CONCATENATE($C2,"Interface/Cameras/GetJPEGStream?Camera=",$E2,"&AuthUser=",$I2,"&AuthPass=",$J2,"&Width=1024&Height=768&Quality=70&FPS=10&ResponseFormat=Text"),IF($L2 = "Axxon",CONCATENATE($K2,"://",$I2,":",$J2,"@",$C2,":",$D2,"/live/media/",$N2,"/DeviceIpint.",$E2,"/SourceEndpoint.video:0:0?w=1024&h=768"),"#")),"#") -> https://monitoramento.pm.pr.gov.br/proxy_image_1/Interface/Cameras/GetJPEGStream?Camera=Camera01&AuthUser=copom_DDTQ&AuthPass=DDTQcopom&Width=1024&Height=768&Quality=70&FPS=10&ResponseFormat=Text | P2: 1
A3: URBS 1 | B3: CURITIBA | C3: https://monitoramento.pm.pr.gov.br/proxy_image_1/ | D3: 18601 | E3: Camera02 | F3: Ubaldino Amaral x Visc. Guarapuava | G3: -25.432082 | H3: -49.256586 | I3: copom_DDTQ | J3: DDTQcopom | K3: https | L3: Digifort | M3: mjpg | N3: =$A3 -> URBS 1 | O3: =IF($P3=1,IF($L3 = "Digifort",CONCATENATE($C3,"Interface/Cameras/GetJPEGStream?Camera=",$E3,"&AuthUser=",$I3,"&AuthPass=",$J3,"&Width=1024&Height=768&Quality=70&FPS=10&ResponseFormat=Text"),IF($L3 = "Axxon",CONCATENATE($K3,"://",$I3,":",$J3,"@",$C3,":",$D3,"/live/media/",$N3,"/DeviceIpint.",$E3,"/SourceEndpoint.video:0:0?w=1024&h=768"),"#")),"#") -> https://monitoramento.pm.pr.gov.br/proxy_image_1/Interface/Cameras/GetJPEGStream?Camera=Camera02&AuthUser=copom_DDTQ&AuthPass=DDTQcopom&Width=1024&Height=768&Quality=70&FPS=10&ResponseFormat=Text | P3: 1
A4: URBS 1 | B4: CURITIBA | C4: https://monitoramento.pm.pr.gov.br/proxy_image_1/ | D4: 18601 | E4: Camera03 | F4: XV de Novembro x Jose de Alencar | G4: -25.426727 | H4: -49.253624 | I4: copom_DDTQ | J4: DDTQcopom | K4: https | L4: Digifort | M4: mjpg | N4: =$A4 -> URBS 1 | O4: =IF($P4=1,IF($L4 = "Digifort",CONCATENATE($C4,"Interface/Cameras/GetJPEGStream?Camera=",$E4,"&AuthUser=",$I4,"&AuthPass=",$J4,"&Width=1024&Height=768&Quality=70&FPS=10&ResponseFormat=Text"),IF($L4 = "Axxon",CONCATENATE($K4,"://",$I4,":",$J4,"@",$C4,":",$D4,"/live/media/",$N4,"/DeviceIpint.",$E4,"/SourceEndpoint.video:0:0?w=1024&h=768"),"#")),"#") -> https://monitoramento.pm.pr.gov.br/proxy_image_1/Interface/Cameras/GetJPEGStream?Camera=Camera03&AuthUser=copom_DDTQ&AuthPass=DDTQcopom&Width=1024&Height=768&Quality=70&FPS=10&ResponseFormat=Text | P4: 1
A5: URBS 1 | B5: CURITIBA | C5: https://monitoramento.pm.pr.gov.br/proxy_image_1/ | D5: 18601 | E5: Camera04 | F5: Sete de Abril x Amintas de Barros | G5: -25.423742 | H5: -49.255794 | I5: copom_DDTQ | J5: DDTQcopom | K5: https | L5: Digifort | M5: mjpg | N5: =$A5 -> URBS 1 | O5: =IF($P5=1,IF($L5 = "Digifort",CONCATENATE($C5,"Interface/Cameras/GetJPEGStream?Camera=",$E5,"&AuthUser=",$I5,"&AuthPass=",$J5,"&Width=1024&Height=768&Quality=70&FPS=10&ResponseFormat=Text"),IF($L5 = "Axxon",CONCATENATE($K5,"://",$I5,":",$J5,"@",$C5,":",$D5,"/live/media/",$N5,"/DeviceIpint.",$E5,"/SourceEndpoint.video:0:0?w=1024&h=768"),"#")),"#") -> https://monitoramento.pm.pr.gov.br/proxy_image_1/Interface/Cameras/GetJPEGStream?Camera=Camera04&AuthUser=copom_DDTQ&AuthPass=DDTQcopom&Width=1024&Height=768&Quality=70&FPS=10&ResponseFormat=Text | P5: 1
A6: URBS 1 | B6: CURITIBA | C6: https://monitoramento.pm.pr.gov.br/proxy_image_1/ | D6: 18601 | E6: Camera05 | F6: Ubaldino Amaral x Itupava | G6: -25.424725 | H6: -49.259819 | I6: copom_DDTQ | J6: DDTQcopom | K6: https | L6: Digifort | M6: mjpg | N6: =$A6 -> URBS 1 | O6: =IF($P6=1,IF($L6 = "Digifort",CONCATENATE($C6,"Interface/Cameras/GetJPEGStream?Camera=",$E6,"&AuthUser=",$I6,"&AuthPass=",$J6,"&Width=1024&Height=768&Quality=70&FPS=10&ResponseFormat=Text"),IF($L6 = "Axxon",CONCATENATE($K6,"://",$I6,":",$J6,"@",$C6,":",$D6,"/live/media/",$N6,"/DeviceIpint.",$E6,"/SourceEndpoint.video:0:0?w=1024&h=768"),"#")),"#") -> https://monitoramento.pm.pr.gov.br/proxy_image_1/Interface/Cameras/GetJPEGStream?Camera=Camera05&AuthUser=copom_DDTQ&AuthPass=DDTQcopom&Width=1024&Height=768&Quality=70&FPS=10&ResponseFormat=Text | P6: 1
A7: URBS 1 | B7: CURITIBA | C7: https://monitoramento.pm.pr.gov.br/proxy_image_1/ | D7: 18601 | E7: Camera06 | F7: Maua x Amancio Moro | G7: -25.419905 | H7: -49.259927 | I7: copom_DDTQ | J7: DDTQcopom | K7: https | L7: Digifort | M7: mjpg | N7: =$A7 -> URBS 1 | O7: =IF($P7=1,IF($L7 = "Digifort",CONCATENATE($C7,"Interface/Cameras/GetJPEGStream?Camera=",$E7,"&AuthUser=",$I7,"&AuthPass=",$J7,"&Width=1024&Height=768&Quality=70&FPS=10&ResponseFormat=Text"),IF($L7 = "Axxon",CONCATENATE($K7,"://",$I7,":",$J7,"@",$C7,":",$D7,"/live/media/",$N7,"/DeviceIpint.",$E7,"/SourceEndpoint.video:0:0?w=1024&h=768"),"#")),"#") -> https://monitoramento.pm.pr.gov.br/proxy_image_1/Interface/Cameras/GetJPEGStream?Camera=Camera06&AuthUser=copom_DDTQ&AuthPass=DDTQcopom&Width=1024&Height=768&Quality=70&FPS=10&ResponseFormat=Text | P7: 1
A8: URBS 1 | B8: CURITIBA | C8: https://monitoramento.pm.pr.gov.br/proxy_image_1/ | D8: 18601 | E8: Camera07 | F8: Campos Sales Augusto Severino | G8: -25.416214 | H8: -49.262683 | I8: copom_DDTQ | J8: DDTQcopom | K8: https | L8: Digifort | M8: mjpg | N8: =$A8 -> URBS 1 | O8: =IF($P8=1,IF($L8 = "Digifort",CONCATENATE($C8,"Interface/Cameras/GetJPEGStream?Camera=",$E8,"&AuthUser=",$I8,"&AuthPass=",$J8,"&Width=1024&Height=768&Quality=70&FPS=10&ResponseFormat=Text"),IF($L8 = "Axxon",CONCATENATE($K8,"://",$I8,":",$J8,"@",$C8,":",$D8,"/live/media/",$N8,"/DeviceIpint.",$E8,"/SourceEndpoint.video:0:0?w=1024&h=768"),"#")),"#") -> https://monitoramento.pm.pr.gov.br/proxy_image_1/Interface/Cameras/GetJPEGStream?Camera=Camera07&AuthUser=copom_DDTQ&AuthPass=DDTQcopom&Width=1024&Height=768&Quality=70&FPS=10&ResponseFormat=Text | P8: 1
A9: URBS 1 | B9: CURITIBA | C9: https://monitoramento.pm.pr.gov.br/proxy_image_1/ | D9: 18601 | E9: Camera08 | F9: Des. Motta x Martim Afonso | G9: -25.428931 | H9: -49.286066 | I9: copom_DDTQ | J9: DDTQcopom | K9: https | L9: Digifort | M9: mjpg | N9: =$A9 -> URBS 1 | O9: =IF($P9=1,IF($L9 = "Digifort",CONCATENATE($C9,"Interface/Cameras/GetJPEGStream?Camera=",$E9,"&AuthUser=",$I9,"&AuthPass=",$J9,"&Width=1024&Height=768&Quality=70&FPS=10&ResponseFormat=Text"),IF($L9 = "Axxon",CONCATENATE($K9,"://",$I9,":",$J9,"@",$C9,":",$D9,"/live/media/",$N9,"/DeviceIpint.",$E9,"/SourceEndpoint.video:0:0?w=1024&h=768"),"#")),"#") -> https://monitoramento.pm.pr.gov.br/proxy_image_1/Interface/Cameras/GetJPEGStream?Camera=Camera08&AuthUser=copom_DDTQ&AuthPass=DDTQcopom&Width=1024&Height=768&Quality=70&FPS=10&ResponseFormat=Text | P9: 1
A10: URBS 1 | B10: CURITIBA | C10: https://monitoramento.pm.pr.gov.br/proxy_image_1/ | D10: 18601 | E10: Camera09 | F10: Lysimaco F. Costa x Candido de Abreu | G10: -25.417569 | H10: -49.268569 | I10: copom_DDTQ | J10: DDTQcopom | K10: https | L10: Digifort | M10: mjpg | N10: =$A10 -> URBS 1 | O10: =IF($P10=1,IF($L10 = "Digifort",CONCATENATE($C10,"Interface/Cameras/GetJPEGStream?Camera=",$E10,"&AuthUser=",$I10,"&AuthPass=",$J10,"&Width=1024&Height=768&Quality=70&FPS=10&ResponseFormat=Text"),IF($L10 = "Axxon",CONCATENATE($K10,"://",$I10,":",$J10,"@",$C10,":",$D10,"/live/media/",$N10,"/DeviceIpint.",$E10,"/SourceEndpoint.video:0:0?w=1024&h=768"),"#")),"#") -> https://monitoramento.pm.pr.gov.br/proxy_image_1/Interface/Cameras/GetJPEGStream?Camera=Camera09&AuthUser=copom_DDTQ&AuthPass=DDTQcopom&Width=1024&Height=768&Quality=70&FPS=10&ResponseFormat=Text | P10: 1
A11: URBS 1 | B11: CURITIBA | C11: https://monitoramento.pm.pr.gov.br/proxy_image_1/ | D11: 18601 | E11: Camera10 | F11: Roberto Barroso x Mateus Leme | G11: -25.418142 | H11: -49.271116 | I11: copom_DDTQ | J11: DDTQcopom | K11: https | L11: Digifort | M11: mjpg | N11: =$A11 -> URBS 1 | O11: =IF($P11=1,IF($L11 = "Digifort",CONCATENATE($C11,"Interface/Cameras/GetJPEGStream?Camera=",$E11,"&AuthUser=",$I11,"&AuthPass=",$J11,"&Width=1024&Height=768&Quality=70&FPS=10&ResponseFormat=Text"),IF($L11 = "Axxon",CONCATENATE($K11,"://",$I11,":",$J11,"@",$C11,":",$D11,"/live/media/",$N11,"/DeviceIpint.",$E11,"/SourceEndpoint.video:0:0?w=1024&h=768"),"#")),"#") -> https://monitoramento.pm.pr.gov.br/proxy_image_1/Interface/Cameras/GetJPEGStream?Camera=Camera10&AuthUser=copom_DDTQ&AuthPass=DDTQcopom&Width=1024&Height=768&Quality=70&FPS=10&ResponseFormat=Text | P11: 1
A12: URBS 1 | B12: CURITIBA | C12: https://monitoramento.pm.pr.gov.br/proxy_image_1/ | D12: 18601 | E12: Camera11 | F12: Des Motta x Manoel Ribas | G12: -25.422483 | H12: -49.289099 | I12: copom_DDTQ | J12: DDTQcopom | K12: https | L12: Digifort | M12: mjpg | N12: =$A12 -> URBS 1 | O12: =IF($P12=1,IF($L12 = "Digifort",CONCATENATE($C12,"Interface/Cameras/GetJPEGStream?Camera=",$E12,"&AuthUser=",$I12,"&AuthPass=",$J12,"&Width=1024&Height=768&Quality=70&FPS=10&ResponseFormat=Text"),IF($L12 = "Axxon",CONCATENATE($K12,"://",$I12,":",$J12,"@",$C12,":",$D12,"/live/media/",$N12,"/DeviceIpint.",$E12,"/SourceEndpoint.video:0:0?w=1024&h=768"),"#")),"#") -> https://monitoramento.pm.pr.gov.br/proxy_image_1/Interface/Cameras/GetJPEGStream?Camera=Camera11&AuthUser=copom_DDTQ&AuthPass=DDTQcopom&Width=1024&Height=768&Quality=70&FPS=10&ResponseFormat=Text | P12: 1
A13: URBS 1 | B13: CURITIBA | C13: https://monitoramento.pm.pr.gov.br/proxy_image_1/ | D13: 18601 | E13: Camera12 | F13: Brig. Franco x Padre Agostinho | G13: -25.426126 | H13: -49.285706 | I13: copom_DDTQ | J13: DDTQcopom | K13: https | L13: Digifort | M13: mjpg | N13: =$A13 -> URBS 1 | O13: =IF($P13=1,IF($L13 = "Digifort",CONCATENATE($C13,"Interface/Cameras/GetJPEGStream?Camera=",$E13,"&AuthUser=",$I13,"&AuthPass=",$J13,"&Width=1024&Height=768&Quality=70&FPS=10&ResponseFormat=Text"),IF($L13 = "Axxon",CONCATENATE($K13,"://",$I13,":",$J13,"@",$C13,":",$D13,"/live/media/",$N13,"/DeviceIpint.",$E13,"/SourceEndpoint.video:0:0?w=1024&h=768"),"#")),"#") -> https://monitoramento.pm.pr.gov.br/proxy_image_1/Interface/Cameras/GetJPEGStream?Camera=Camera12&AuthUser=copom_DDTQ&AuthPass=DDTQcopom&Width=1024&Height=768&Quality=70&FPS=10&ResponseFormat=Text | P13: 1
... A98: URBS 2 | B98: CURITIBA | C98: https://monitoramento.pm.pr.gov.br/proxy_image_2/ | D98: 28601 | E98: Camera76 | F98: ET Joao Viana Seiler | G98: -25.454429 | H98: -49.260433 | I98: copom_DDTQ | J98: DDTQcopom | K98: https | L98: Digifort | M98: mjpg | N98: =$A98 -> URBS 2 | O98: =IF($P98=1,IF($L98 = "Digifort",CONCATENATE($C98,"Interface/Cameras/GetJPEGStream?Camera=",$E98,"&AuthUser=",$I98,"&AuthPass=",$J98,"&Width=1024&Height=768&Quality=70&FPS=10&ResponseFormat=Text"),IF($L98 = "Axxon",CONCATENATE($K98,"://",$I98,":",$J98,"@",$C98,":",$D98,"/live/media/",$N98,"/DeviceIpint.",$E98,"/SourceEndpoint.video:0:0?w=1024&h=768"),"#")),"#") -> https://monitoramento.pm.pr.gov.br/proxy_image_2/Interface/Cameras/GetJPEGStream?Camera=Camera76&AuthUser=copom_DDTQ&AuthPass=DDTQcopom&Width=1024&Height=768&Quality=70&FPS=10&ResponseFormat=Text | P98: 1
A99: URBS 2 | B99: CURITIBA | C99: https://monitoramento.pm.pr.gov.br/proxy_image_2/ | D99: 28601 | E99: Camera77 | F99: PANE | G99: 0 | H99: 0 | I99: copom_DDTQ | J99: DDTQcopom | K99: https | L99: Digifort | M99: mjpg | N99: =$A99 -> URBS 2 | O99: =IF($P99=1,IF($L99 = "Digifort",CONCATENATE($C99,"Interface/Cameras/GetJPEGStream?Camera=",$E99,"&AuthUser=",$I99,"&AuthPass=",$J99,"&Width=1024&Height=768&Quality=70&FPS=10&ResponseFormat=Text"),IF($L99 = "Axxon",CONCATENATE($K99,"://",$I99,":",$J99,"@",$C99,":",$D99,"/live/media/",$N99,"/DeviceIpint.",$E99,"/SourceEndpoint.video:0:0?w=1024&h=768"),"#")),"#") -> https://monitoramento.pm.pr.gov.br/proxy_image_2/Interface/Cameras/GetJPEGStream?Camera=Camera77&AuthUser=copom_DDTQ&AuthPass=DDTQcopom&Width=1024&Height=768&Quality=70&FPS=10&ResponseFormat=Text | P99: 1
A100: URBS 2 | B100: CURITIBA | C100: https://monitoramento.pm.pr.gov.br/proxy_image_2/ | D100: 28601 | E100: Camera78 | F100: PANE | G100: 0 | H100: 0 | I100: copom_DDTQ | J100: DDTQcopom | K100: https | L100: Digifort | M100: mjpg | N100: =$A100 -> URBS 2 | O100: =IF($P100=1,IF($L100 = "Digifort",CONCATENATE($C100,"Interface/Cameras/GetJPEGStream?Camera=",$E100,"&AuthUser=",$I100,"&AuthPass=",$J100,"&Width=1024&Height=768&Quality=70&FPS=10&ResponseFormat=Text"),IF($L100 = "Axxon",CONCATENATE($K100,"://",$I100,":",$J100,"@",$C100,":",$D100,"/live/media/",$N100,"/DeviceIpint.",$E100,"/SourceEndpoint.video:0:0?w=1024&h=768"),"#")),"#") -> https://monitoramento.pm.pr.gov.br/proxy_image_2/Interface/Cameras/GetJPEGStream?Camera=Camera78&AuthUser=copom_DDTQ&AuthPass=DDTQcopom&Width=1024&Height=768&Quality=70&FPS=10&ResponseFormat=Text | P100: 1
A101: URBS 2 | B101: CURITIBA | C101: https://monitoramento.pm.pr.gov.br/proxy_image_2/ | D101: 28601 | E101: Camera79 | F101: ET Ferrovila> Boqueirao | G101: -25.440251 | H101: -49.221176 | I101: copom_DDTQ | J101: DDTQcopom | K101: https | L101: Digifort | M101: mjpg | N101: =$A101 -> URBS 2 | O101: =IF($P101=1,IF($L101 = "Digifort",CONCATENATE($C101,"Interface/Cameras/GetJPEGStream?Camera=",$E101,"&AuthUser=",$I101,"&AuthPass=",$J101,"&Width=1024&Height=768&Quality=70&FPS=10&ResponseFormat=Text"),IF($L101 = "Axxon",CONCATENATE($K101,"://",$I101,":",$J101,"@",$C101,":",$D101,"/live/media/",$N101,"/DeviceIpint.",$E101,"/SourceEndpoint.video:0:0?w=1024&h=768"),"#")),"#") -> https://monitoramento.pm.pr.gov.br/proxy_image_2/Interface/Cameras/GetJPEGStream?Camera=Camera79&AuthUser=copom_DDTQ&AuthPass=DDTQcopom&Width=1024&Height=768&Quality=70&FPS=10&ResponseFormat=Text | P101: 1
A102: URBS 2 | B102: CURITIBA | C102: https://monitoramento.pm.pr.gov.br/proxy_image_2/ | D102: 28601 | E102: Camera80 | F102: PANE | G102: 0 | H102: 0 | I102: copom_DDTQ | J102: DDTQcopom | K102: https | L102: Digifort | M102: mjpg | N102: =$A102 -> URBS 2 | O102: =IF($P102=1,IF($L102 = "Digifort",CONCATENATE($C102,"Interface/Cameras/GetJPEGStream?Camera=",$E102,"&AuthUser=",$I102,"&AuthPass=",$J102,"&Width=1024&Height=768&Quality=70&FPS=10&ResponseFormat=Text"),IF($L102 = "Axxon",CONCATENATE($K102,"://",$I102,":",$J102,"@",$C102,":",$D102,"/live/media/",$N102,"/DeviceIpint.",$E102,"/SourceEndpoint.video:0:0?w=1024&h=768"),"#")),"#") -> https://monitoramento.pm.pr.gov.br/proxy_image_2/Interface/Cameras/GetJPEGStream?Camera=Camera80&AuthUser=copom_DDTQ&AuthPass=DDTQcopom&Width=1024&Height=768&Quality=70&FPS=10&ResponseFormat=Text | P102: 1
A103: URBS 2 | B103: CURITIBA | C103: https://monitoramento.pm.pr.gov.br/proxy_image_2/ | D103: 28601 | E103: Camera81 | F103: ET Pç Carlos gomes catraca | G103: -25.433733 | H103: -49.270370 | I103: copom_DDTQ | J103: DDTQcopom | K103: https | L103: Digifort | M103: mjpg | N103: =$A103 -> URBS 2 | O103: =IF($P103=1,IF($L103 = "Digifort",CONCATENATE($C103,"Interface/Cameras/GetJPEGStream?Camera=",$E103,"&AuthUser=",$I103,"&AuthPass=",$J103,"&Width=1024&Height=768&Quality=70&FPS=10&ResponseFormat=Text"),IF($L103 = "Axxon",CONCATENATE($K103,"://",$I103,":",$J103,"@",$C103,":",$D103,"/live/media/",$N103,"/DeviceIpint.",$E103,"/SourceEndpoint.video:0:0?w=1024&h=768"),"#")),"#") -> https://monitoramento.pm.pr.gov.br/proxy_image_2/Interface/Cameras/GetJPEGStream?Camera=Camera81&AuthUser=copom_DDTQ&AuthPass=DDTQcopom&Width=1024&Height=768&Quality=70&FPS=10&ResponseFormat=Text | P103: 1
A104: URBS 2 | B104: CURITIBA | C104: https://monitoramento.pm.pr.gov.br/proxy_image_2/ | D104: 28601 | E104: Camera82 | F104: ET Pç Carlos gomes catraca | G104: -25.433675 | H104: -49.270208 | I104: copom_DDTQ | J104: DDTQcopom | K104: https | L104: Digifort | M104: mjpg | N104: =$A104 -> URBS 2 | O104: =IF($P104=1,IF($L104 = "Digifort",CONCATENATE($C104,"Interface/Cameras/GetJPEGStream?Camera=",$E104,"&AuthUser=",$I104,"&AuthPass=",$J104,"&Width=1024&Height=768&Quality=70&FPS=10&ResponseFormat=Text"),IF($L104 = "Axxon",CONCATENATE($K104,"://",$I104,":",$J104,"@",$C104,":",$D104,"/live/media/",$N104,"/DeviceIpint.",$E104,"/SourceEndpoint.video:0:0?w=1024&h=768"),"#")),"#") -> https://monitoramento.pm.pr.gov.br/proxy_image_2/Interface/Cameras/GetJPEGStream?Camera=Camera82&AuthUser=copom_DDTQ&AuthPass=DDTQcopom&Width=1024&Height=768&Quality=70&FPS=10&ResponseFormat=Text | P104: 1
A105: URBS 2 | B105: CURITIBA | C105: https://monitoramento.pm.pr.gov.br/proxy_image_2/ | D105: 28601 | E105: Camera83 | F105: ET Pç Carlos gomes catraca | G105: -25.433686 | H105: -49.270257 | I105: copom_DDTQ | J105: DDTQcopom | K105: https | L105: Digifort | M105: mjpg | N105: =$A105 -> URBS 2 | O105: =IF($P105=1,IF($L105 = "Digifort",CONCATENATE($C105,"Interface/Cameras/GetJPEGStream?Camera=",$E105,"&AuthUser=",$I105,"&AuthPass=",$J105,"&Width=1024&Height=768&Quality=70&FPS=10&ResponseFormat=Text"),IF($L105 = "Axxon",CONCATENATE($K105,"://",$I105,":",$J105,"@",$C105,":",$D105,"/live/media/",$N105,"/DeviceIpint.",$E105,"/SourceEndpoint.video:0:0?w=1024&h=768"),"#")),"#") -> https://monitoramento.pm.pr.gov.br/proxy_image_2/Interface/Cameras/GetJPEGStream?Camera=Camera83&AuthUser=copom_DDTQ&AuthPass=DDTQcopom&Width=1024&Height=768&Quality=70&FPS=10&ResponseFormat=Text | P105: 1
A106: URBS 2 | B106: CURITIBA | C106: https://monitoramento.pm.pr.gov.br/proxy_image_2/ | D106: 28601 | E106: Camera84 | F106: ET Pç Carlos gomes pinheirinho | G106: -25.433945 | H106: -49.269181 | I106: copom_DDTQ | J106: DDTQcopom | K106: https | L106: Digifort | M106: mjpg | N106: =$A106 -> URBS 2 | O106: =IF($P106=1,IF($L106 = "Digifort",CONCATENATE($C106,"Interface/Cameras/GetJPEGStream?Camera=",$E106,"&AuthUser=",$I106,"&AuthPass=",$J106,"&Width=1024&Height=768&Quality=70&FPS=10&ResponseFormat=Text"),IF($L106 = "Axxon",CONCATENATE($K106,"://",$I106,":",$J106,"@",$C106,":",$D106,"/live/media/",$N106,"/DeviceIpint.",$E106,"/SourceEndpoint.video:0:0?w=1024&h=768"),"#")),"#") -> https://monitoramento.pm.pr.gov.br/proxy_image_2/Interface/Cameras/GetJPEGStream?Camera=Camera84&AuthUser=copom_DDTQ&AuthPass=DDTQcopom&Width=1024&Height=768&Quality=70&FPS=10&ResponseFormat=Text | P106: 1
A107: URBS 2 | B107: CURITIBA | C107: https://monitoramento.pm.pr.gov.br/proxy_image_2/ | D107: 28601 | E107: Camera85 | F107: ET Pç Carlos gomes pinheirinho | G107: -25.434041 | H107: -49.269159 | I107: copom_DDTQ | J107: DDTQcopom | K107: https | L107: Digifort | M107: mjpg | N107: =$A107 -> URBS 2 | O107: =IF($P107=1,IF($L107 = "Digifort",CONCATENATE($C107,"Interface/Cameras/GetJPEGStream?Camera=",$E107,"&AuthUser=",$I107,"&AuthPass=",$J107,"&Width=1024&Height=768&Quality=70&FPS=10&ResponseFormat=Text"),IF($L107 = "Axxon",CONCATENATE($K107,"://",$I107,":",$J107,"@",$C107,":",$D107,"/live/media/",$N107,"/DeviceIpint.",$E107,"/SourceEndpoint.video:0:0?w=1024&h=768"),"#")),"#") -> https://monitoramento.pm.pr.gov.br/proxy_image_2/Interface/Cameras/GetJPEGStream?Camera=Camera85&AuthUser=copom_DDTQ&AuthPass=DDTQcopom&Width=1024&Height=768&Quality=70&FPS=10&ResponseFormat=Text | P107: 1
A108: URBS 2 | B108: CURITIBA | C108: https://monitoramento.pm.pr.gov.br/proxy_image_2/ | D108: 28601 | E108: Camera86 | F108: ET Pç Carlos gomes pinheirinho | G108: -25.434096 | H108: -49.269135 | I108: copom_DDTQ | J108: DDTQcopom | K108: https | L108: Digifort | M108: mjpg | N108: =$A108 -> URBS 2 | O108: =IF($P108=1,IF($L108 = "Digifort",CONCATENATE($C108,"Interface/Cameras/GetJPEGStream?Camera=",$E108,"&AuthUser=",$I108,"&AuthPass=",$J108,"&Width=1024&Height=768&Quality=70&FPS=10&ResponseFormat=Text"),IF($L108 = "Axxon",CONCATENATE($K108,"://",$I108,":",$J108,"@",$C108,":",$D108,"/live/media/",$N108,"/DeviceIpint.",$E108,"/SourceEndpoint.video:0:0?w=1024&h=768"),"#")),"#") -> https://monitoramento.pm.pr.gov.br/proxy_image_2/Interface/Cameras/GetJPEGStream?Camera=Camera86&AuthUser=copom_DDTQ&AuthPass=DDTQcopom&Width=1024&Height=768&Quality=70&FPS=10&ResponseFormat=Text | P108: 1
A109: URBS 2 | B109: CURITIBA | C109: https://monitoramento.pm.pr.gov.br/proxy_image_2/ | D109: 28601 | E109: Camera87 | F109: ET Pç Rui barbosa> Pinhais | G109: -25.436537 | H109: -49.273971 | I109: copom_DDTQ | J109: DDTQcopom | K109: https | L109: Digifort | M109: mjpg | N109: =$A109 -> URBS 2 | O109: =IF($P109=1,IF($L109 = "Digifort",CONCATENATE($C109,"Interface/Cameras/GetJPEGStream?Camera=",$E109,"&AuthUser=",$I109,"&AuthPass=",$J109,"&Width=1024&Height=768&Quality=70&FPS=10&ResponseFormat=Text"),IF($L109 = "Axxon",CONCATENATE($K109,"://",$I109,":",$J109,"@",$C109,":",$D109,"/live/media/",$N109,"/DeviceIpint.",$E109,"/SourceEndpoint.video:0:0?w=1024&h=768"),"#")),"#") -> https://monitoramento.pm.pr.gov.br/proxy_image_2/Interface/Cameras/GetJPEGStream?Camera=Camera87&AuthUser=copom_DDTQ&AuthPass=DDTQcopom&Width=1024&Height=768&Quality=70&FPS=10&ResponseFormat=Text | P109: 1
A110: URBS 2 | B110: CURITIBA | C110: https://monitoramento.pm.pr.gov.br/proxy_image_2/ | D110: 28601 | E110: Camera88 | F110: ET Pç Carlos gomes>boqueirao | G110: -25.433762 | H110: -49.270323 | I110: copom_DDTQ | J110: DDTQcopom | K110: https | L110: Digifort | M110: mjpg | N110: =$A110 -> URBS 2 | O110: =IF($P110=1,IF($L110 = "Digifort",CONCATENATE($C110,"Interface/Cameras/GetJPEGStream?Camera=",$E110,"&AuthUser=",$I110,"&AuthPass=",$J110,"&Width=1024&Height=768&Quality=70&FPS=10&ResponseFormat=Text"),IF($L110 = "Axxon",CONCATENATE($K110,"://",$I110,":",$J110,"@",$C110,":",$D110,"/live/media/",$N110,"/DeviceIpint.",$E110,"/SourceEndpoint.video:0:0?w=1024&h=768"),"#")),"#") -> https://monitoramento.pm.pr.gov.br/proxy_image_2/Interface/Cameras/GetJPEGStream?Camera=Camera88&AuthUser=copom_DDTQ&AuthPass=DDTQcopom&Width=1024&Height=768&Quality=70&FPS=10&ResponseFormat=Text | P110: 1
A111: URBS 2 | B111: CURITIBA | C111: https://monitoramento.pm.pr.gov.br/proxy_image_2/ | D111: 28601 | E111: Camera90 | F111: ET Pç Carlos gomes>boqueirao | G111: -25.433706 | H111: -49.270329 | I111: copom_DDTQ | J111: DDTQcopom | K111: https | L111: Digifort | M111: mjpg | N111: =$A111 -> URBS 2 | O111: =IF($P111=1,IF($L111 = "Digifort",CONCATENATE($C111,"Interface/Cameras/GetJPEGStream?Camera=",$E111,"&AuthUser=",$I111,"&AuthPass=",$J111,"&Width=1024&Height=768&Quality=70&FPS=10&ResponseFormat=Text"),IF($L111 = "Axxon",CONCATENATE($K111,"://",$I111,":",$J111,"@",$C111,":",$D111,"/live/media/",$N111,"/DeviceIpint.",$E111,"/SourceEndpoint.video:0:0?w=1024&h=768"),"#")),"#") -> https://monitoramento.pm.pr.gov.br/proxy_image_2/Interface/Cameras/GetJPEGStream?Camera=Camera90&AuthUser=copom_DDTQ&AuthPass=DDTQcopom&Width=1024&Height=768&Quality=70&FPS=10&ResponseFormat=Text | P111: 1
A112: URBS 2 | B112: CURITIBA | C112: https://monitoramento.pm.pr.gov.br/proxy_image_2/ | D112: 28601 | E112: Camera91 | F112: ET Pç Carlos gomes pinheirinho | G112: -25.433923 | H112: -49.269216 | I112: copom_DDTQ | J112: DDTQcopom | K112: https | L112: Digifort | M112: mjpg | N112: =$A112 -> URBS 2 | O112: =IF($P112=1,IF($L112 = "Digifort",CONCATENATE($C112,"Interface/Cameras/GetJPEGStream?Camera=",$E112,"&AuthUser=",$I112,"&AuthPass=",$J112,"&Width=1024&Height=768&Quality=70&FPS=10&ResponseFormat=Text"),IF($L112 = "Axxon",CONCATENATE($K112,"://",$I112,":",$J112,"@",$C112,":",$D112,"/live/media/",$N112,"/DeviceIpint.",$E112,"/SourceEndpoint.video:0:0?w=1024&h=768"),"#")),"#") -> https://monitoramento.pm.pr.gov.br/proxy_image_2/Interface/Cameras/GetJPEGStream?Camera=Camera91&AuthUser=copom_DDTQ&AuthPass=DDTQcopom&Width=1024&Height=768&Quality=70&FPS=10&ResponseFormat=Text | P112: 1
A113: URBS 2 | B113: CURITIBA | C113: https://monitoramento.pm.pr.gov.br/proxy_image_2/ | D113: 28601 | E113: Camera92 | F113: ET Pç Carlos gomes>boqueirao des. | G113: -25.433638 | H113: -49.269993 | I113: copom_DDTQ | J113: DDTQcopom | K113: https | L113: Digifort | M113: mjpg | N113: =$A113 -> URBS 2 | O113: =IF($P113=1,IF($L113 = "Digifort",CONCATENATE($C113,"Interface/Cameras/GetJPEGStream?Camera=",$E113,"&AuthUser=",$I113,"&AuthPass=",$J113,"&Width=1024&Height=768&Quality=70&FPS=10&ResponseFormat=Text"),IF($L113 = "Axxon",CONCATENATE($K113,"://",$I113,":",$J113,"@",$C113,":",$D113,"/live/media/",$N113,"/DeviceIpint.",$E113,"/SourceEndpoint.video:0:0?w=1024&h=768"),"#")),"#") -> https://monitoramento.pm.pr.gov.br/proxy_image_2/Interface/Cameras/GetJPEGStream?Camera=Camera92&AuthUser=copom_DDTQ&AuthPass=DDTQcopom&Width=1024&Height=768&Quality=70&FPS=10&ResponseFormat=Text | P113: 1
A114: URBS 2 | B114: CURITIBA | C114: https://monitoramento.pm.pr.gov.br/proxy_image_2/ | D114: 28601 | E114: Camera93 | F114: ET Pç Rui barbosa> Pinhais des. | G114: -25.433638 | H114: -49.269993 | I114: copom_DDTQ | J114: DDTQcopom | K114: https | L114: Digifort | M114: mjpg | N114: =$A114 -> URBS 2 | O114: =IF($P114=1,IF($L114 = "Digifort",CONCATENATE($C114,"Interface/Cameras/GetJPEGStream?Camera=",$E114,"&AuthUser=",$I114,"&AuthPass=",$J114,"&Width=1024&Height=768&Quality=70&FPS=10&ResponseFormat=Text"),IF($L114 = "Axxon",CONCATENATE($K114,"://",$I114,":",$J114,"@",$C114,":",$D114,"/live/media/",$N114,"/DeviceIpint.",$E114,"/SourceEndpoint.video:0:0?w=1024&h=768"),"#")),"#") -> https://monitoramento.pm.pr.gov.br/proxy_image_2/Interface/Cameras/GetJPEGStream?Camera=Camera93&AuthUser=copom_DDTQ&AuthPass=DDTQcopom&Width=1024&Height=768&Quality=70&FPS=10&ResponseFormat=Text | P114: 1
... A394: URBS 3 | B394: CURITIBA | C394: https://monitoramento.pm.pr.gov.br/proxy_image_3/ | D394: 38601 | E394: TE010CFTV10 | F394: Terminal Capão Raso > ET Inter II > CIC > Cabral | G394: -25.492077 | H394: -49.293057 | I394: copom_DDTQ | J394: DDTQcopom | K394: https | L394: Digifort | M394: mjpg | N394: =$A394 -> URBS 3 | O394: =IF($P394=1,IF($L394 = "Digifort",CONCATENATE($C394,"Interface/Cameras/GetJPEGStream?Camera=",$E394,"&AuthUser=",$I394,"&AuthPass=",$J394,"&Width=1024&Height=768&Quality=70&FPS=10&ResponseFormat=Text"),IF($L394 = "Axxon",CONCATENATE($K394,"://",$I394,":",$J394,"@",$C394,":",$D394,"/live/media/",$N394,"/DeviceIpint.",$E394,"/SourceEndpoint.video:0:0?w=1024&h=768"),"#")),"#") -> https://monitoramento.pm.pr.gov.br/proxy_image_3/Interface/Cameras/GetJPEGStream?Camera=TE010CFTV10&AuthUser=copom_DDTQ&AuthPass=DDTQcopom&Width=1024&Height=768&Quality=70&FPS=10&ResponseFormat=Text | P394: 1
A395: URBS 3 | B395: CURITIBA | C395: https://monitoramento.pm.pr.gov.br/proxy_image_3/ | D395: 38601 | E395: TE010CFTV11 | F395: Terminal Capão Raso > Sitio Cercado > Horario | G395: 0 | H395: 0 | I395: copom_DDTQ | J395: DDTQcopom | K395: https | L395: Digifort | M395: mjpg | N395: =$A395 -> URBS 3 | O395: =IF($P395=1,IF($L395 = "Digifort",CONCATENATE($C395,"Interface/Cameras/GetJPEGStream?Camera=",$E395,"&AuthUser=",$I395,"&AuthPass=",$J395,"&Width=1024&Height=768&Quality=70&FPS=10&ResponseFormat=Text"),IF($L395 = "Axxon",CONCATENATE($K395,"://",$I395,":",$J395,"@",$C395,":",$D395,"/live/media/",$N395,"/DeviceIpint.",$E395,"/SourceEndpoint.video:0:0?w=1024&h=768"),"#")),"#") -> https://monitoramento.pm.pr.gov.br/proxy_image_3/Interface/Cameras/GetJPEGStream?Camera=TE010CFTV11&AuthUser=copom_DDTQ&AuthPass=DDTQcopom&Width=1024&Height=768&Quality=70&FPS=10&ResponseFormat=Text | P395: 1
A396: URBS 3 | B396: CURITIBA | C396: https://monitoramento.pm.pr.gov.br/proxy_image_3/ | D396: 38601 | E396: TE010CFTV12 | F396: Terminal Capão Raso > Entrada 1 | G396: -25.492477 | H396: -49.293015 | I396: copom_DDTQ | J396: DDTQcopom | K396: https | L396: Digifort | M396: mjpg | N396: =$A396 -> URBS 3 | O396: =IF($P396=1,IF($L396 = "Digifort",CONCATENATE($C396,"Interface/Cameras/GetJPEGStream?Camera=",$E396,"&AuthUser=",$I396,"&AuthPass=",$J396,"&Width=1024&Height=768&Quality=70&FPS=10&ResponseFormat=Text"),IF($L396 = "Axxon",CONCATENATE($K396,"://",$I396,":",$J396,"@",$C396,":",$D396,"/live/media/",$N396,"/DeviceIpint.",$E396,"/SourceEndpoint.video:0:0?w=1024&h=768"),"#")),"#") -> https://monitoramento.pm.pr.gov.br/proxy_image_3/Interface/Cameras/GetJPEGStream?Camera=TE010CFTV12&AuthUser=copom_DDTQ&AuthPass=DDTQcopom&Width=1024&Height=768&Quality=70&FPS=10&ResponseFormat=Text | P396: 1
A397: URBS 3 | B397: CURITIBA | C397: https://monitoramento.pm.pr.gov.br/proxy_image_3/ | D397: 38601 | E397: TE010CFTV13 | F397: Terminal Capão Raso > Expresso Pinheirinho | G397: -25.491783 | H397: -49.293661 | I397: copom_DDTQ | J397: DDTQcopom | K397: https | L397: Digifort | M397: mjpg | N397: =$A397 -> URBS 3 | O397: =IF($P397=1,IF($L397 = "Digifort",CONCATENATE($C397,"Interface/Cameras/GetJPEGStream?Camera=",$E397,"&AuthUser=",$I397,"&AuthPass=",$J397,"&Width=1024&Height=768&Quality=70&FPS=10&ResponseFormat=Text"),IF($L397 = "Axxon",CONCATENATE($K397,"://",$I397,":",$J397,"@",$C397,":",$D397,"/live/media/",$N397,"/DeviceIpint.",$E397,"/SourceEndpoint.video:0:0?w=1024&h=768"),"#")),"#") -> https://monitoramento.pm.pr.gov.br/proxy_image_3/Interface/Cameras/GetJPEGStream?Camera=TE010CFTV13&AuthUser=copom_DDTQ&AuthPass=DDTQcopom&Width=1024&Height=768&Quality=70&FPS=10&ResponseFormat=Text | P397: 1
A398: URBS 3 | B398: CURITIBA | C398: https://monitoramento.pm.pr.gov.br/proxy_image_3/ | D398: 38601 | E398: TE010CFTV14 | F398: Terminal Capão Raso > Entrada 2 | G398: -25.492398 | H398: -49.293616 | I398: copom_DDTQ | J398: DDTQcopom | K398: https | L398: Digifort | M398: mjpg | N398: =$A398 -> URBS 3 | O398: =IF($P398=1,IF($L398 = "Digifort",CONCATENATE($C398,"Interface/Cameras/GetJPEGStream?Camera=",$E398,"&AuthUser=",$I398,"&AuthPass=",$J398,"&Width=1024&Height=768&Quality=70&FPS=10&ResponseFormat=Text"),IF($L398 = "Axxon",CONCATENATE($K398,"://",$I398,":",$J398,"@",$C398,":",$D398,"/live/media/",$N398,"/DeviceIpint.",$E398,"/SourceEndpoint.video:0:0?w=1024&h=768"),"#")),"#") -> https://monitoramento.pm.pr.gov.br/proxy_image_3/Interface/Cameras/GetJPEGStream?Camera=TE010CFTV14&AuthUser=copom_DDTQ&AuthPass=DDTQcopom&Width=1024&Height=768&Quality=70&FPS=10&ResponseFormat=Text | P398: 1
A399: URBS 3 | B399: CURITIBA | C399: https://monitoramento.pm.pr.gov.br/proxy_image_3/ | D399: 38601 | E399: TE010CFTV15 | F399: Terminal Capão Raso > Entrada 3 | G399: -25.492236 | H399: -49.293346 | I399: copom_DDTQ | J399: DDTQcopom | K399: https | L399: Digifort | M399: mjpg | N399: =$A399 -> URBS 3 | O399: =IF($P399=1,IF($L399 = "Digifort",CONCATENATE($C399,"Interface/Cameras/GetJPEGStream?Camera=",$E399,"&AuthUser=",$I399,"&AuthPass=",$J399,"&Width=1024&Height=768&Quality=70&FPS=10&ResponseFormat=Text"),IF($L399 = "Axxon",CONCATENATE($K399,"://",$I399,":",$J399,"@",$C399,":",$D399,"/live/media/",$N399,"/DeviceIpint.",$E399,"/SourceEndpoint.video:0:0?w=1024&h=768"),"#")),"#") -> https://monitoramento.pm.pr.gov.br/proxy_image_3/Interface/Cameras/GetJPEGStream?Camera=TE010CFTV15&AuthUser=copom_DDTQ&AuthPass=DDTQcopom&Width=1024&Height=768&Quality=70&FPS=10&ResponseFormat=Text | P399: 1
A400: URBS 3 | B400: CURITIBA | C400: https://monitoramento.pm.pr.gov.br/proxy_image_3/ | D400: 38601 | E400: TE010CFTV16 | F400: Terminal Capão Raso > Vila São Pedro | G400: -25.492267 | H400: -49.293255 | I400: copom_DDTQ | J400: DDTQcopom | K400: https | L400: Digifort | M400: mjpg | N400: =$A400 -> URBS 3 | O400: =IF($P400=1,IF($L400 = "Digifort",CONCATENATE($C400,"Interface/Cameras/GetJPEGStream?Camera=",$E400,"&AuthUser=",$I400,"&AuthPass=",$J400,"&Width=1024&Height=768&Quality=70&FPS=10&ResponseFormat=Text"),IF($L400 = "Axxon",CONCATENATE($K400,"://",$I400,":",$J400,"@",$C400,":",$D400,"/live/media/",$N400,"/DeviceIpint.",$E400,"/SourceEndpoint.video:0:0?w=1024&h=768"),"#")),"#") -> https://monitoramento.pm.pr.gov.br/proxy_image_3/Interface/Cameras/GetJPEGStream?Camera=TE010CFTV16&AuthUser=copom_DDTQ&AuthPass=DDTQcopom&Width=1024&Height=768&Quality=70&FPS=10&ResponseFormat=Text | P400: 1
A401: URBS 3 | B401: CURITIBA | C401: https://monitoramento.pm.pr.gov.br/proxy_image_3/ | D401: 38601 | E401: TE010CFTV17 | F401: Terminal Capão Raso > Entrada 4 | G401: -25.492226 | H401: -49.293030 | I401: copom_DDTQ | J401: DDTQcopom | K401: https | L401: Digifort | M401: mjpg | N401: =$A401 -> URBS 3 | O401: =IF($P401=1,IF($L401 = "Digifort",CONCATENATE($C401,"Interface/Cameras/GetJPEGStream?Camera=",$E401,"&AuthUser=",$I401,"&AuthPass=",$J401,"&Width=1024&Height=768&Quality=70&FPS=10&ResponseFormat=Text"),IF($L401 = "Axxon",CONCATENATE($K401,"://",$I401,":",$J401,"@",$C401,":",$D401,"/live/media/",$N401,"/DeviceIpint.",$E401,"/SourceEndpoint.video:0:0?w=1024&h=768"),"#")),"#") -> https://monitoramento.pm.pr.gov.br/proxy_image_3/Interface/Cameras/GetJPEGStream?Camera=TE010CFTV17&AuthUser=copom_DDTQ&AuthPass=DDTQcopom&Width=1024&Height=768&Quality=70&FPS=10&ResponseFormat=Text | P401: 1
A402: URBS 3 | B402: CURITIBA | C402: https://monitoramento.pm.pr.gov.br/proxy_image_3/ | D402: 38601 | E402: TE011CFTV01 | F402: Terminal Carmo > Expresso> Centro | G402: -25.501797 | H402: -49.237450 | I402: copom_DDTQ | J402: DDTQcopom | K402: https | L402: Digifort | M402: mjpg | N402: =$A402 -> URBS 3 | O402: =IF($P402=1,IF($L402 = "Digifort",CONCATENATE($C402,"Interface/Cameras/GetJPEGStream?Camera=",$E402,"&AuthUser=",$I402,"&AuthPass=",$J402,"&Width=1024&Height=768&Quality=70&FPS=10&ResponseFormat=Text"),IF($L402 = "Axxon",CONCATENATE($K402,"://",$I402,":",$J402,"@",$C402,":",$D402,"/live/media/",$N402,"/DeviceIpint.",$E402,"/SourceEndpoint.video:0:0?w=1024&h=768"),"#")),"#") -> https://monitoramento.pm.pr.gov.br/proxy_image_3/Interface/Cameras/GetJPEGStream?Camera=TE011CFTV01&AuthUser=copom_DDTQ&AuthPass=DDTQcopom&Width=1024&Height=768&Quality=70&FPS=10&ResponseFormat=Text | P402: 1
A403: URBS 3 | B403: CURITIBA | C403: https://monitoramento.pm.pr.gov.br/proxy_image_3/ | D403: 38601 | E403: TE011CFTV02 | F403: Terminal Carmo > Interbairros III > Capão raso | G403: -25.501154 | H403: -49.237680 | I403: copom_DDTQ | J403: DDTQcopom | K403: https | L403: Digifort | M403: mjpg | N403: =$A403 -> URBS 3 | O403: =IF($P403=1,IF($L403 = "Digifort",CONCATENATE($C403,"Interface/Cameras/GetJPEGStream?Camera=",$E403,"&AuthUser=",$I403,"&AuthPass=",$J403,"&Width=1024&Height=768&Quality=70&FPS=10&ResponseFormat=Text"),IF($L403 = "Axxon",CONCATENATE($K403,"://",$I403,":",$J403,"@",$C403,":",$D403,"/live/media/",$N403,"/DeviceIpint.",$E403,"/SourceEndpoint.video:0:0?w=1024&h=768"),"#")),"#") -> https://monitoramento.pm.pr.gov.br/proxy_image_3/Interface/Cameras/GetJPEGStream?Camera=TE011CFTV02&AuthUser=copom_DDTQ&AuthPass=DDTQcopom&Width=1024&Height=768&Quality=70&FPS=10&ResponseFormat=Text | P403: 1
...

Sheet GMC CURITIBA
A1: Nome | B1: Descrição
A2: CAM 01 | B2: 01 - Praça Santos Andrade - Frente a UFPR - CTA1260
A3: CAM 02 | B3: 02 - Praça Santos Andrade - Fixa
A4: CAM 03 | B4: 03 - Rua XV, nº 621- ACP esquina com Rua Presidente Faria
A5: CAM 04 | B5: 04 - R. XV esquina com R. Barão do Rio Branco, n°525 - CTA1262
A6: CAM 05 | B6: 05 - Rua XV, n° 382 - Lojas Rener - CTA1264
A7: CAM 06 | B7: 06 - Rua XV esquina Rua Monsenhor Celso, n°98 - Banco Itaú - CTA1265
A8: CAM 07 | B8: 07 - Rua XV, n°245 - Loja Marisa - CTA 1266
A9: CAM 08 | B9: 08 - Rua XV com Av. Marechal Floriano Peixoto - Galeria Ritz - CTA1267
A10: CAM 09 | B10: 09 - Rua XV nº 141 - Frente a Loja C&A - CTA1268
A11: CAM 10 | B11: 10 - Rua XV, n° 41 - Loja Prata Fina - CTA1269
A12: CAM 101 | B12: 101 - Rua da Cidadania Boqueirão - Canchas
... A122: CAM 98 | B122: 98 - R. Izaac Ferreira da Cruz n° 3391, com R. São José dos Pinhais - Fixa
A125: CONTATO ICI CURITIBA: TEC. THIAGO: 41 99848-9366

Sheet SISCOP
B1: BARRACÃO
A2: NOME | B2: LINK | C2: ENDEREÇO | D2: LATITUDE | E2: LONGITUDE | F2: BATALHÃO
A3: camera 01 | B3: rtsp://siscop:siscop@10.47.142.100:554/Interface/Cameras/Media?Camera=BRC_VGT_001 | C3: Avenida Arnaldo Busato x BR-280 | D3: -26.257627 | E3: -53.618633 | F3: 21 BPM | G3: -26.2576271,-53.6186331 | I3: =substitute(RIGHT(B3, LEN(B3)-SEARCH("=",B3)),".",".") -> BRC_VGT_001
A4: camera 02 | B4: rtsp://siscop:siscop@10.47.142.100:554/Interface/Cameras/Media?Camera=BRC_CEN_002 | C4: Rua Geni Damiani X Rua Pedro Poleto | D4: -26.257037 | E4: -53.628141 | F4: 21 BPM | G4: -26.2570373,-53.6281410 | I4: =substitute(RIGHT(B4, LEN(B4)-SEARCH("=",B4)),".",".") -> BRC_CEN_002
A5: camera 03 | B5: rtsp://siscop:siscop@10.47.142.100:554/Interface/Cameras/Media?Camera=BRC_CEN_003 | C5: Avenida Brasília X Rua T. Neves | D5: -26.251002 | E5: -53.63561 | F5: 21 BPM | G5: -26.2510022,-53.6356097 | I5: =substitute(RIGHT(B5, LEN(B5)-SEARCH("=",B5)),".",".") -> BRC_CEN_003
A6: camera 04 | B6: rtsp://siscop:siscop@10.47.142.100:554/Interface/Cameras/Media?Camera=BRC_ALV_004 | C6: Rua Amazonas X Rua Minas Gerais | D6: -26.249102 | E6: -53.636099 | F6: 21 BPM | G6: -26.2491024,-53.6360990 | I6: =substitute(RIGHT(B6, LEN(B6)-SEARCH("=",B6)),".",".") -> BRC_ALV_004
A7: camera 05 | B7: rtsp://siscop:siscop@10.47.142.100:554/Interface/Cameras/Media?Camera=BRC_FNT_005 | C7: Rua Rep. Argentina X Av. Brasil | D7: -26.249684 | E7: -53.637182 | F7: 21 BPM | G7: -26.2496836,-53.6371820 | I7: =substitute(RIGHT(B7, LEN(B7)-SEARCH("=",B7)),".",".") -> BRC_FNT_005
A8: camera 06 | B8: rtsp://siscop:siscop@10.47.142.100:554/Interface/Cameras/Media?Camera=BRC_FNT_006 | C8: Rua Goias X Cristalino | D8: -26.252019 | E8: -53.638837 | F8: 21 BPM | G8: -26.2520192,-53.6388366 | I8: =substitute(RIGHT(B8, LEN(B8)-SEARCH("=",B8)),".",".") -> BRC_FNT_006
A9: camera 07 | B9: rtsp://siscop:siscop@10.47.142.100:554/Interface/Cameras/Media?Camera=BRC_FNT_007 | C9: Rua Rio Grande do Sul X Rua 7 de Setembro | D9: -26.254777 | E9: -53.636182 | F9: 21 BPM | G9: -26.2547771,-53.6361819 | I9: =substitute(RIGHT(B9, LEN(B9)-SEARCH("=",B9)),".",".") -> BRC_FNT_007
A10: camera 08 | B10: rtsp://siscop:siscop@10.47.142.100:554/Interface/Cameras/Media?Camera=BRC_CEN_008 | C10: Rua Rio Grande do Sul X Rua Bahia | D10: -26.253593 | E10: -53.63571 | F10: 21 BPM | G10: -26.2535929,-53.6357097 | I10: =substitute(RIGHT(B10, LEN(B10)-SEARCH("=",B10)),".",".") -> BRC_CEN_008
A11: camera 09 | B11: rtsp://siscop:siscop@10.47.142.100:554/Interface/Cameras/Media?Camera=BRC_FNT_009 | C11: Avenida Paraná – em frente ao Colégio Judite Guarente | D11: -26.257554 | E11: -53.630212 | F11: 21 BPM | G11: -26.2575538,-53.6302116 | I11: =substitute(RIGHT(B11, LEN(B11)-SEARCH("=",B11)),".",".") -> BRC_FNT_009
A12: camera 10 | B12: rtsp://siscop:siscop@10.47.142.100:554/Interface/Cameras/Media?Camera=BRC_CEN_010 | C12: Destacameto Policia Militar | D12: -26.25731 | E12: -53.628189 | F12: 21 BPM | G12: -26.2573100,-53.6281890 | I12: =substitute(RIGHT(B12, LEN(B12)-SEARCH("=",B12)),".",".") -> BRC_CEN_010
A13: camera 11 | B13: rtsp://10.47.142.98:554/H264?ch=1-8&subtype=0 | C13: Destacameto Policia Militar | D13: -26.257286 | E13: -53.628304 | F13: 21 BPM | G13: -26.2572860,-53.6283040 | I13: =substitute(RIGHT(B13, LEN(B13)-SEARCH("=",B13)),".",".") -> 1-8&subtype=0
A14: camera 12 | B14: rtsp://10.47.142.98:554/H264?ch=2-8&subtype=0 | C14: Destacameto Policia Militar | D14: -26.257286 | E14: -53.628304 | F14: 21 BPM | G14: -26.2572860,-53.6283040 | I14: =substitute(RIGHT(B14, LEN(B14)-SEARCH("=",B14)),".",".") -> 2-8&subtype=0
... A17: camera 15 | B17: rtsp://10.47.142.98:554/H264?ch=5-8&subtype=0 | C17: Destacameto Policia Militar | D17: -26.257268 | E17: -53.628626 | F17: 21 BPM | G17: -26.2572680,-53.6286260 | I17: =substitute(RIGHT(B17, LEN(B17)-SEARCH("=",B17)),".",".") -> 5-8&subtype=0
B18: SANTO ANTONIO DO SUDOESTE
A19: NOME | B19: LINK | C19: ENDEREÇO | D19: LATITUDE | E19: LONGITUDE | F19: BATALHÃO
A20: camera 01 | B20: rtsp://siscop:siscop@10.47.136.100:554/Interface/Cameras/Media?Camera=STA_ENT_001 | C20: Alfandega | D20: -26.056857 | E20: -53.730064 | F20: 21 BPM | G20: -26.056857, -53.730064
A21: camera 02 | B21: rtsp://siscop:siscop@10.47.136.100:554/Interface/Cameras/Media?Camera=STA_ENT_002 | C21: Avenida Ramalho Piva X BR 168 - Saída Pranchita | D21: -26.058044 | E21: -53.726420 | F21: 21 BPM | G21: -26.058044, -53.726420
A22: camera 03 | B22: rtsp://siscop:siscop@10.47.136.100:554/Interface/Cameras/Media?Camera=STA_EMB_003 | C22: Trevo BR 163 - Saída Ampere | D22: -26.059267 | E22: -53.719973 | F22: 21 BPM | G22: -26.059267, -53.719973
A23: camera 04 | B23: rtsp://siscop:siscop@10.47.136.100:554/Interface/Cameras/Media?Camera=STA_ARI_004 | C23: Rua Jesuíno Teodorico de Andrade – Trevo BR 163 | D23: -26.074927 | E23: -53.719062 | F23: 21 BPM | G23: -26.074927, -53.719062
A24: camera 05 | B24: rtsp://siscop:siscop@10.47.136.100:554/Interface/Cameras/Media?Camera=STA_CEN_005 | C24: Avenida Brasil n⁰ 500 - Obelisco | D24: -26.072946 | E24: -53.725773 | F24: 21 BPM | G24: -26.072946, -53.725773
A25: camera 06 | B25: rtsp://siscop:siscop@10.47.136.100:554/Interface/Cameras/Media?Camera=STA_CEN_006 | C25: Avenida Brasil em frente ao n⁰ 301 - Rodoviária | D25: -26.075140 | E25: -53.722765 | F25: 21 BPM | G25: -26.075140, -53.722765
A26: camera 07 | B26: rtsp://siscop:siscop@10.47.136.100:554/Interface/Cameras/Media?Camera=STA_AUR_007 | C26: Rua Tancredo Neves X Rua Arnaldo Sorensen - Vila Aurora | D26: -26.055795 | E26: -53.723456 | F26: 21 BPM | G26: -26.055795, -53.723456
A27: camera 08 | B27: rtsp://siscop:siscop@10.47.136.100:554/Interface/Cameras/Media?Camera=STA_NOV_008 | C27: Avenida Brasil n°1547 - Posto Foquezatto | D27: -26.065286 | E27: -53.725891 | F27: 21 BPM | G27: -26.065286, -53.725891
A28: camera 09 | B28: rtsp://siscop:siscop@10.47.136.100:554/Interface/Cameras/Media?Camera=STA_PRI_009 | C28: Rua Dom Pedro I X Avenida Brasil | D28: -26.071459 | E28: -53.725670 | F28: 21 BPM | G28: -26.071459, -53.725670
A29: camera 10 | B29: rtsp://siscop:siscop@10.47.136.100:554/Interface/Cameras/Media?Camera=STA_CEN_010 | C29: Destacameto Policia Militar | D29: -26.071440 | E29: -53.730423 | F29: 21 BPM | G29: -26.071440, -53.730423
B30: SANTA HELENA
A31: NOME | B31: LINK | C31: ENDEREÇO | D31: LATITUDE | E31: LONGITUDE | F31: BATALHÃO
A32: camera 01 | B32: rtsp://siscop:siscop@10.47.150.100:554/Interface/Cameras/Media?Camera=STH_ALA_001 | C32: Rua Ângelo Catani x Rua Vereador José Biesdorf | D32: -24.87235 | E32: -54.3342 | F32: 19 BPM | G32: -24.87235, -54.3342
A33: camera 02 | B33: rtsp://siscop:siscop@10.47.150.100:554/Interface/Cameras/Media?Camera=STH_BXA_002 | C33: Rua Vereador José Biesdorf X Rua Para | D33: -24.86906 | E33: -54.34392 | F33: 19 BPM | G33: -24.86906, -54.34392
A34: camera 03 | B34: rtsp://siscop:siscop@10.47.150.100:554/Interface/Cameras/Media?Camera=STH_FRN_003 | C34: Rua do Porto x Rua Argentina | D34: -24.8765 | E34: -54.34565 | F34: 19 BPM | G34: -24.8765, -54.34565
A35: camera 04 | B35: rtsp://siscop:siscop@10.47.150.100:554/Interface/Cameras/Media?Camera=STH_CEN_004 | C35: Avenida Curitiba X Avenida Brasil | D35: -24.85896 | E35: -54.33463 | F35: 19 BPM | G35: -24.85896, -54.33463
A36: camera 05 | B36: rtsp://siscop:siscop@10.47.150.100:554/Interface/Cameras/Media?Camera=STH_CEN_005 | C36: Avenida Deputado Arnaldo Busato x Avenida Paraná | D36: -24.85901 | E36: -54.33225 | F36: 19 BPM | G36: -24.85901, -54.33225
A37: camera 06 | B37: rtsp://siscop:siscop@10.47.150.100:554/Interface/Cameras/Media?Camera=STH_CEN_006 | C37: Avenida Curitiba X Rua Angelo Catani | D37: -24.86056 | E37: -54.32975 | F37: 19 BPM | G37: -24.86056, -54.32975
A38: camera 07 | B38: rtsp://siscop:siscop@10.47.150.100:554/Interface/Cameras/Media?Camera=STH_BXA_007 | C38: Rua Angelo Catani x Rua Paraguai | D38: -24.84694 | E38: -54.32857 | F38: 19 BPM | G38: -24.84694, -54.32857
A39: camera 08 | B39: rtsp://siscop:siscop@10.47.150.100:554/Interface/Cameras/Media?Camera=STH_BXA_008 | C39: Avenida Brasil X Rua Angelo Catani | D39: -24.84644 | E39: -54.32944 | F39: 19 BPM | G39: -24.84644, -54.32944
A40: camera 09 | B40: rtsp://siscop:siscop@10.47.150.100:554/Interface/Cameras/Media?Camera=STH_BXA_009 | C40: Avenida Brasil X Praça Santos Dumont | D40: -24.85428 | E40: -54.33259 | F40: 19 BPM | G40: -24.85428, -54.33259
A41: camera 10 | B41: rtsp://siscop:siscop@10.47.150.100:554/Interface/Cameras/Media?Camera=STH_VRC_010 | C41: Prolongamento da Rua Argentina Sentido Porto, s/n - Zona Rural | D41: -24.87806 | E41: -54.34212 | F41: 19 BPM | G41: -24.87806, -54.34212
B42: SÃO MIGUEL DO IGUAÇU
...

Sheet Proxy
A1: Proxy | B1: IP | C1: Porta | D1: Servidor | E1: Cidade
A2: proxy_image_1 | B2: 10.247.206.2 | C2: 18601 | D2: DIGIFORT | E2: CURITIBA
A3: proxy_image_2 | B3: 10.247.206.2 | C3: 28601 | D3: DIGIFORT | E3: CURITIBA
A4: proxy_image_3 | B4: 10.247.206.2 | C4: 38601 | D4: DIGIFORT | E4: CURITIBA
A5: proxy_image_4 | B5: 10.247.206.2 | C5: 48601 | D5: DIGIFORT | E5: CURITIBA
A6: proxy_image_5 | B6: 10.247.206.2 | C6: 58601 | D6: DIGIFORT
A7: proxy_image_6 | B7: 10.247.220.201 | C7: 8601 | D7: DIGIFORT
A8: proxy_image_7 | B8: 10.247.217.201 | C8: 8601 | D8: DIGIFORT
A9: proxy_image_8 | B9: 10.247.231.201 | C9: 8601 | D9: DIGIFORT
A10: proxy_image_9 | B10: 10.247.236.201 | C10: 8601 | D10: DIGIFORT
A11: proxy_image_10 | B11: 10.247.234.201 | C11: 8601 | D11: DIGIFORT
A12: proxy_image_11 | B12: 10.247.234.201 | C12: 8601 | D12: DIGIFORT
A13: proxy_image_12 | B13: 10.247.241.201 | C13: 8601 | D13: DIGIFORT
A14: proxy_image_13 | B14: 10.247.219.201 | C14: 8601 | D14: DIGIFORT
A15: proxy_image_14 | B15: 10.248.007.201 | C15: 8601 | D15: DIGIFORT
A16: proxy_image_15 | B16: 10.247.235.201 | C16: 8601 | D16: DIGIFORT
A17: proxy_image_16 | B17: 10.247.206.201 | C17: 8601 | D17: DIGIFORT | E17: CURITIBA
A18: proxy_image_17 | B18: 10 247 213 201 | C18: 8601 | D18: DIGIFORT | E18: FAZENDA RIO GRANDE
A19: proxy_image_18 | B19: 10 247 216 201 | C19: 8601 | D19: DIGIFORT | E19: COLOMBO
A20: proxy_image_19 | B20: 10 248 002 201 | C20: 8601 | D20: DIGIFORT | E20: GUAÍRA
A21: proxy_image_20 | B21: 10 247 218 201 | C21: 8601 | D21: DIGIFORT | E21: PARANAGUÁ
A22: proxy_image_21 | B22: 10247232201 | C22: 8601 | D22: DIGIFORT | E22: TELEMACO BORBA
A23: proxy_image_22 | B23: 10248000201 | C23: 8601 | D23: DIGIFORT | E23: UBIRATÃ
A24: proxy_image_23
A25: proxy_image_24
A26: proxy_image_25
A27: proxy_image_26
A28: proxy_image_27
A29: proxy_image_28
A30: proxy_image_29

Sheet Importação monitoramento
A1: servidor | B1: cidade | C1: ip | D1: porta | E1: camera | F1: local_nome | G1: lat | H1: lng | I1: usuario | J1: senha | K1: protocolo | L1: vms | M1: formato | N1: hostname | O1: link | P1: ativo
A2: =Cadastro!$A2 -> URBS 1 | B2: =Cadastro!$B2 -> CURITIBA | C2: =Cadastro!$C2 -> https://monitoramento.pm.pr.gov.br/proxy_image_1/ | D2: =Cadastro!$D2 -> 18601 | E2: =Cadastro!$E2 -> Camera01 | F2: =Cadastro!$F2 -> Brasilio Itibere x Com. Franco | G2: =Cadastro!$G2 -> -25.440635 | H2: =Cadastro!$H2 -> -49.25217 | I2: =Cadastro!$I2 -> copom_DDTQ | J2: =Cadastro!$J2 -> DDTQcopom | K2: http | L2: Digifort | M2: mjpg | N2: =$A2 -> URBS 1 | O2: =Cadastro!$O2 -> https://monitoramento.pm.pr.gov.br/proxy_image_1/Interface/Cameras/GetJPEGStream?Camera=Camera01&AuthUser=copom_DDTQ&AuthPass=DDTQcopom&Width=1024&Height=768&Quality=70&FPS=10&ResponseFormat=Text | P2: =Cadastro!$P2 -> 1
A3: =Cadastro!$A3 -> URBS 1 | B3: =Cadastro!$B3 -> CURITIBA | C3: =Cadastro!$C3 -> https://monitoramento.pm.pr.gov.br/proxy_image_1/ | D3: =Cadastro!$D3 -> 18601 | E3: =Cadastro!$E3 -> Camera02 | F3: =Cadastro!$F3 -> Ubaldino Amaral x Visc. Guarapuava | G3: =Cadastro!$G3 -> -25.432082 | H3: =Cadastro!$H3 -> -49.256586 | I3: =Cadastro!$I3 -> copom_DDTQ | J3: =Cadastro!$J3 -> DDTQcopom | K3: http | L3: Digifort | M3: mjpg | N3: =$A3 -> URBS 1 | O3: =Cadastro!$O3 -> https://monitoramento.pm.pr.gov.br/proxy_image_1/Interface/Cameras/GetJPEGStream?Camera=Camera02&AuthUser=copom_DDTQ&AuthPass=DDTQcopom&Width=1024&Height=768&Quality=70&FPS=10&ResponseFormat=Text | P3: =Cadastro!$P3 -> 1
A4: =Cadastro!$A4 -> URBS 1 | B4: =Cadastro!$B4 -> CURITIBA | C4: =Cadastro!$C4 -> https://monitoramento.pm.pr.gov.br/proxy_image_1/ | D4: =Cadastro!$D4 -> 18601 | E4: =Cadastro!$E4 -> Camera03 | F4: =Cadastro!$F4 -> XV de Novembro x Jose de Alencar | G4: =Cadastro!$G4 -> -25.426727 | H4: =Cadastro!$H4 -> -49.253624 | I4: =Cadastro!$I4 -> copom_DDTQ | J4: =Cadastro!$J4 -> DDTQcopom | K4: http | L4: Digifort | M4: mjpg | N4: =$A4 -> URBS 1 | O4: =Cadastro!$O4 -> https://monitoramento.pm.pr.gov.br/proxy_image_1/Interface/Cameras/GetJPEGStream?Camera=Camera03&AuthUser=copom_DDTQ&AuthPass=DDTQcopom&Width=1024&Height=768&Quality=70&FPS=10&ResponseFormat=Text | P4: =Cadastro!$P4 -> 1
A5: =Cadastro!$A5 -> URBS 1 | B5: =Cadastro!$B5 -> CURITIBA | C5: =Cadastro!$C5 -> https://monitoramento.pm.pr.gov.br/proxy_image_1/ | D5: =Cadastro!$D5 -> 18601 | E5: =Cadastro!$E5 -> Camera04 | F5: =Cadastro!$F5 -> Sete de Abril x Amintas de Barros | G5: =Cadastro!$G5 -> -25.423742 | H5: =Cadastro!$H5 -> -49.255794 | I5: =Cadastro!$I5 -> copom_DDTQ | J5: =Cadastro!$J5 -> DDTQcopom | K5: http | L5: Digifort | M5: mjpg | N5: =$A5 -> URBS 1 | O5: =Cadastro!$O5 -> https://monitoramento.pm.pr.gov.br/proxy_image_1/Interface/Cameras/GetJPEGStream?Camera=Camera04&AuthUser=copom_DDTQ&AuthPass=DDTQcopom&Width=1024&Height=768&Quality=70&FPS=10&ResponseFormat=Text | P5: =Cadastro!$P5 -> 1
A6: =Cadastro!$A6 -> URBS 1 | B6: =Cadastro!$B6 -> CURITIBA | C6: =Cadastro!$C6 -> https://monitoramento.pm.pr.gov.br/proxy_image_1/ | D6: =Cadastro!$D6 -> 18601 | E6: =Cadastro!$E6 -> Camera05 | F6: =Cadastro!$F6 -> Ubaldino Amaral x Itupava | G6: =Cadastro!$G6 -> -25.424725 | H6: =Cadastro!$H6 -> -49.259819 | I6: =Cadastro!$I6 -> copom_DDTQ | J6: =Cadastro!$J6 -> DDTQcopom | K6: http | L6: Digifort | M6: mjpg | N6: =$A6 -> URBS 1 | O6: =Cadastro!$O6 -> https://monitoramento.pm.pr.gov.br/proxy_image_1/Interface/Cameras/GetJPEGStream?Camera=Camera05&AuthUser=copom_DDTQ&AuthPass=DDTQcopom&Width=1024&Height=768&Quality=70&FPS=10&ResponseFormat=Text | P6: =Cadastro!$P6 -> 1
A7: =Cadastro!$A7 -> URBS 1 | B7: =Cadastro!$B7 -> CURITIBA | C7: =Cadastro!$C7 -> https://monitoramento.pm.pr.gov.br/proxy_image_1/ | D7: =Cadastro!$D7 -> 18601 | E7: =Cadastro!$E7 -> Camera06 | F7: =Cadastro!$F7 -> Maua x Amancio Moro | G7: =Cadastro!$G7 -> -25.419905 | H7: =Cadastro!$H7 -> -49.259927 | I7: =Cadastro!$I7 -> copom_DDTQ | J7: =Cadastro!$J7 -> DDTQcopom | K7: http | L7: Digifort | M7: mjpg | N7: =$A7 -> URBS 1 | O7: =Cadastro!$O7 -> https://monitoramento.pm.pr.gov.br/proxy_image_1/Interface/Cameras/GetJPEGStream?Camera=Camera06&AuthUser=copom_DDTQ&AuthPass=DDTQcopom&Width=1024&Height=768&Quality=70&FPS=10&ResponseFormat=Text | P7: =Cadastro!$P7 -> 1
A8: =Cadastro!$A8 -> URBS 1 | B8: =Cadastro!$B8 -> CURITIBA | C8: =Cadastro!$C8 -> https://monitoramento.pm.pr.gov.br/proxy_image_1/ | D8: =Cadastro!$D8 -> 18601 | E8: =Cadastro!$E8 -> Camera07 | F8: =Cadastro!$F8 -> Campos Sales Augusto Severino | G8: =Cadastro!$G8 -> -25.416214 | H8: =Cadastro!$H8 -> -49.262683 | I8: =Cadastro!$I8 -> copom_DDTQ | J8: =Cadastro!$J8 -> DDTQcopom | K8: http | L8: Digifort | M8: mjpg | N8: =$A8 -> URBS 1 | O8: =Cadastro!$O8 -> https://monitoramento.pm.pr.gov.br/proxy_image_1/Interface/Cameras/GetJPEGStream?Camera=Camera07&AuthUser=copom_DDTQ&AuthPass=DDTQcopom&Width=1024&Height=768&Quality=70&FPS=10&ResponseFormat=Text | P8: =Cadastro!$P8 -> 1
A9: =Cadastro!$A9 -> URBS 1 | B9: =Cadastro!$B9 -> CURITIBA | C9: =Cadastro!$C9 -> https://monitoramento.pm.pr.gov.br/proxy_image_1/ | D9: =Cadastro!$D9 -> 18601 | E9: =Cadastro!$E9 -> Camera08 | F9: =Cadastro!$F9 -> Des. Motta x Martim Afonso | G9: =Cadastro!$G9 -> -25.428931 | H9: =Cadastro!$H9 -> -49.286066 | I9: =Cadastro!$I9 -> copom_DDTQ | J9: =Cadastro!$J9 -> DDTQcopom | K9: http | L9: Digifort | M9: mjpg | N9: =$A9 -> URBS 1 | O9: =Cadastro!$O9 -> https://monitoramento.pm.pr.gov.br/proxy_image_1/Interface/Cameras/GetJPEGStream?Camera=Camera08&AuthUser=copom_DDTQ&AuthPass=DDTQcopom&Width=1024&Height=768&Quality=70&FPS=10&ResponseFormat=Text | P9: =Cadastro!$P9 -> 1
A10: =Cadastro!$A10 -> URBS 1 | B10: =Cadastro!$B10 -> CURITIBA | C10: =Cadastro!$C10 -> https://monitoramento.pm.pr.gov.br/proxy_image_1/ | D10: =Cadastro!$D10 -> 18601 | E10: =Cadastro!$E10 -> Camera09 | F10: =Cadastro!$F10 -> Lysimaco F. Costa x Candido de Abreu | G10: =Cadastro!$G10 -> -25.417569 | H10: =Cadastro!$H10 -> -49.268569 | I10: =Cadastro!$I10 -> copom_DDTQ | J10: =Cadastro!$J10 -> DDTQcopom | K10: http | L10: Digifort | M10: mjpg | N10: =$A10 -> URBS 1 | O10: =Cadastro!$O10 -> https://monitoramento.pm.pr.gov.br/proxy_image_1/Interface/Cameras/GetJPEGStream?Camera=Camera09&AuthUser=copom_DDTQ&AuthPass=DDTQcopom&Width=1024&Height=768&Quality=70&FPS=10&ResponseFormat=Text | P10: =Cadastro!$P10 -> 1
A11: =Cadastro!$A11 -> URBS 1 | B11: =Cadastro!$B11 -> CURITIBA | C11: =Cadastro!$C11 -> https://monitoramento.pm.pr.gov.br/proxy_image_1/ | D11: =Cadastro!$D11 -> 18601 | E11: =Cadastro!$E11 -> Camera10 | F11: =Cadastro!$F11 -> Roberto Barroso x Mateus Leme | G11: =Cadastro!$G11 -> -25.418142 | H11: =Cadastro!$H11 -> -49.271116 | I11: =Cadastro!$I11 -> copom_DDTQ | J11: =Cadastro!$J11 -> DDTQcopom | K11: http | L11: Digifort | M11: mjpg | N11: =$A11 -> URBS 1 | O11: =Cadastro!$O11 -> https://monitoramento.pm.pr.gov.br/proxy_image_1/Interface/Cameras/GetJPEGStream?Camera=Camera10&AuthUser=copom_DDTQ&AuthPass=DDTQcopom&Width=1024&Height=768&Quality=70&FPS=10&ResponseFormat=Text | P11: =Cadastro!$P11 -> 1
A12: =Cadastro!$A12 -> URBS 1 | B12: =Cadastro!$B12 -> CURITIBA | C12: =Cadastro!$C12 -> https://monitoramento.pm.pr.gov.br/proxy_image_1/ | D12: =Cadastro!$D12 -> 18601 | E12: =Cadastro!$E12 -> Camera11 | F12: =Cadastro!$F12 -> Des Motta x Manoel Ribas | G12: =Cadastro!$G12 -> -25.422483 | H12: =Cadastro!$H12 -> -49.289099 | I12: =Cadastro!$I12 -> copom_DDTQ | J12: =Cadastro!$J12 -> DDTQcopom | K12: http | L12: Digifort | M12: mjpg | N12: =$A12 -> URBS 1 | O12: =Cadastro!$O12 -> https://monitoramento.pm.pr.gov.br/proxy_image_1/Interface/Cameras/GetJPEGStream?Camera=Camera11&AuthUser=copom_DDTQ&AuthPass=DDTQcopom&Width=1024&Height=768&Quality=70&FPS=10&ResponseFormat=Text | P12: =Cadastro!$P12 -> 1
A13: =Cadastro!$A13 -> URBS 1 | B13: =Cadastro!$B13 -> CURITIBA | C13: =Cadastro!$C13 -> https://monitoramento.pm.pr.gov.br/proxy_image_1/ | D13: =Cadastro!$D13 -> 18601 | E13: =Cadastro!$E13 -> Camera12 | F13: =Cadastro!$F13 -> Brig. Franco x Padre Agostinho | G13: =Cadastro!$G13 -> -25.426126 | H13: =Cadastro!$H13 -> -49.285706 | I13: =Cadastro!$I13 -> copom_DDTQ | J13: =Cadastro!$J13 -> DDTQcopom | K13: http | L13: Digifort | M13: mjpg | N13: =$A13 -> URBS 1 | O13: =Cadastro!$O13 -> https://monitoramento.pm.pr.gov.br/proxy_image_1/Interface/Cameras/GetJPEGStream?Camera=Camera12&AuthUser=copom_DDTQ&AuthPass=DDTQcopom&Width=1024&Height=768&Quality=70&FPS=10&ResponseFormat=Text | P13: =Cadastro!$P13 -> 1
... A528: =Cadastro!$A528 -> URBS 4 | B528: =Cadastro!$B528 -> CURITIBA | C528: =Cadastro!$C528 -> https://monitoramento.pm.pr.gov.br/proxy_image_4/ | D528: =Cadastro!$D528 -> 48601 | E528: =Cadastro!$E528 -> Camera89 | F528: =Cadastro!$F528 -> ET Carlos Gomes > Pineirinho portas | G528: =Cadastro!$G528 -> -25.434047 | H528: =Cadastro!$H528 -> -49.269153 | I528: =Cadastro!$I528 -> copom_DDTQ | J528: =Cadastro!$J528 -> DDTQcopom | K528: http | L528: Digifort | M528: mjpg | N528: =$A528 -> URBS 4 | O528: =Cadastro!$O528 -> https://monitoramento.pm.pr.gov.br/proxy_image_4/Interface/Cameras/GetJPEGStream?Camera=Camera89&AuthUser=copom_DDTQ&AuthPass=DDTQcopom&Width=1024&Height=768&Quality=70&FPS=10&ResponseFormat=Text | P528: =Cadastro!$P528 -> 1
A529: =#REF! -> #REF! | B529: =#REF! -> #REF! | C529: =#REF! -> #REF! | D529: =#REF! -> #REF! | E529: =#REF! -> #REF! | F529: =#REF! -> #REF! | G529: =#REF! -> #REF! | H529: =#REF! -> #REF! | ... J529: =#REF! -> #REF! | K529: http | L529: Digifort | M529: mjpg | N529: =$A529 -> #REF! | O529: =#REF! -> #REF! | P529: =#REF! -> #REF!
A530: =#REF! -> #REF! | B530: =#REF! -> #REF! | C530: =#REF! -> #REF! | D530: =#REF! -> #REF! | E530: =#REF! -> #REF! | F530: =#REF! -> #REF! | G530: =#REF! -> #REF! | H530: =#REF! -> #REF! | ... J530: =#REF! -> #REF! | K530: http | L530: Digifort | M530: mjpg | N530: =$A530 -> #REF! | O530: =#REF! -> #REF! | P530: =#REF! -> #REF!
A531: =#REF! -> #REF! | B531: =#REF! -> #REF! | C531: =#REF! -> #REF! | D531: =#REF! -> #REF! | E531: =#REF! -> #REF! | F531: =#REF! -> #REF! | G531: =#REF! -> #REF! | H531: =#REF! -> #REF! | ... J531: =#REF! -> #REF! | K531: http | L531: Digifort | M531: mjpg | N531: =$A531 -> #REF! | O531: =#REF! -> #REF! | P531: =#REF! -> #REF!
A532: =#REF! -> #REF! | B532: =#REF! -> #REF! | C532: =#REF! -> #REF! | D532: =#REF! -> #REF! | E532: =#REF! -> #REF! | F532: =#REF! -> #REF! | G532: =#REF! -> #REF! | H532: =#REF! -> #REF! | ... J532: =#REF! -> #REF! | K532: http | L532: Digifort | M532: mjpg | N532: =$A532 -> #REF! | O532: =#REF! -> #REF! | P532: =#REF! -> #REF!
A533: =#REF! -> #REF! | B533: =#REF! -> #REF! | C533: =#REF! -> #REF! | D533: =#REF! -> #REF! | E533: =#REF! -> #REF! | F533: =#REF! -> #REF! | G533: =#REF! -> #REF! | H533: =#REF! -> #REF! | ... J533: =#REF! -> #REF! | K533: http | L533: Digifort | M533: mjpg | N533: =$A533 -> #REF! | O533: =#REF! -> #REF! | P533: =#REF! -> #REF!
A534: =#REF! -> #REF! | B534: =#REF! -> #REF! | C534: =#REF! -> #REF! | D534: =#REF! -> #REF! | E534: =#REF! -> #REF! | F534: =#REF! -> #REF! | G534: =#REF! -> #REF! | H534: =#REF! -> #REF! | ... J534: =#REF! -> #REF! | K534: http | L534: Digifort | M534: mjpg | N534: =$A534 -> #REF! | O534: =#REF! -> #REF! | P534: =#REF! -> #REF!
A535: =#REF! -> #REF! | B535: =#REF! -> #REF! | C535: =#REF! -> #REF! | D535: =#REF! -> #REF! | E535: =#REF! -> #REF! | F535: =#REF! -> #REF! | G535: =#REF! -> #REF! | H535: =#REF! -> #REF! | ... J535: =#REF! -> #REF! | K535: http | L535: Digifort | M535: mjpg | N535: =$A535 -> #REF! | O535: =#REF! -> #REF! | P535: =#REF! -> #REF!
A536: =#REF! -> #REF! | B536: =#REF! -> #REF! | C536: =#REF! -> #REF! | D536: =#REF! -> #REF! | E536: =#REF! -> #REF! | F536: =#REF! -> #REF! | G536: =#REF! -> #REF! | H536: =#REF! -> #REF! | ... J536: =#REF! -> #REF! | K536: http | L536: Digifort | M536: mjpg | N536: =$A536 -> #REF! | O536: =#REF! -> #REF! | P536: =#REF! -> #REF!
A537: =#REF! -> #REF! | B537: =#REF! -> #REF! | C537: =#REF! -> #REF! | D537: =#REF! -> #REF! | E537: =#REF! -> #REF! | F537: =#REF! -> #REF! | G537: =#REF! -> #REF! | H537: =#REF! -> #REF! | ... J537: =#REF! -> #REF! | K537: http | L537: Digifort | M537: mjpg | N537: =$A537 -> #REF! | O537: =#REF! -> #REF! | P537: =#REF! -> #REF!
A538: =#REF! -> #REF! | B538: =#REF! -> #REF! | C538: =#REF! -> #REF! | D538: =#REF! -> #REF! | E538: =#REF! -> #REF! | F538: =#REF! -> #REF! | G538: =#REF! -> #REF! | H538: =#REF! -> #REF! | ... J538: =#REF! -> #REF! | K538: http | L538: Digifort | M538: mjpg | N538: =$A538 -> #REF! | O538: =#REF! -> #REF! | P538: =#REF! -> #REF!
A539: =#REF! -> #REF! | B539: =#REF! -> #REF! | C539: =#REF! -> #REF! | D539: =#REF! -> #REF! | E539: =#REF! -> #REF! | F539: =#REF! -> #REF! | G539: =#REF! -> #REF! | H539: =#REF! -> #REF! | ... J539: =#REF! -> #REF! | K539: http | L539: Digifort | M539: mjpg | N539: =$A539 -> #REF! | O539: =#REF! -> #REF! | P539: =#REF! -> #REF!
A540: =#REF! -> #REF! | B540: =#REF! -> #REF! | C540: =#REF! -> #REF! | D540: =#REF! -> #REF! | E540: =#REF! -> #REF! | F540: =#REF! -> #REF! | G540: =#REF! -> #REF! | H540: =#REF! -> #REF! | ... J540: =#REF! -> #REF! | K540: http | L540: Digifort | M540: mjpg | N540: =$A540 -> #REF! | O540: =#REF! -> #REF! | P540: =#REF! -> #REF!
... A596: =#REF! -> #REF! | B596: =#REF! -> #REF! | C596: =#REF! -> #REF! | D596: =#REF! -> #REF! | E596: =#REF! -> #REF! | F596: =#REF! -> #REF! | G596: =#REF! -> #REF! | H596: =#REF! -> #REF! | ... J596: =#REF! -> #REF! | K596: http | L596: Digifort | M596: mjpg | N596: =$A596 -> #REF! | O596: =#REF! -> #REF! | P596: =#REF! -> #REF!
